Workbook
Name Six: '[1]6-Months'!$A$17:$S$1334
Name Sixes2: '[2]MOF 6M'!$A$7:$J$1130
Name Three: '[1]3-Months'!$A$9:$T$1555
Name three1: '[2]MOF 3M'!$A$6:$J$288
Name Twelve: '[1]12-Months'!$A$18:$S$1478
Name Twelves1: '[2]MOF 12M'!$A$7:$J$1662

Sheet Summary
A1: HABIB BANK LIMITED | C1: PKR | E1: PKR | G1: PKR | I1: PKR | K1: PKR
A2: RATIOS | C2: 25 Forecast | E2: 24 | G2: 23 | I2: 22 | K2: 21
A3: Total Assets | C3: =SOFP!$D$14 -> 6.8380813e+09 | E3: =SOFP!$F$14 -> 6055112877 | G3: =SOFP!$H$14 -> 5,534,348,303 | I3: =SOFP!$J$14 -> 4638806111 | K3: =SOFP!$L$14 -> 4317468145
A4: Total Equity | C4: =SOFP!$D$25 -> 4.5145751e+08 | E4: =SOFP!$F$25 -> 410798094 | G4: =SOFP!$H$25 -> 366020653 | I4: =SOFP!$J$25 -> 285021814 | K4: =SOFP!$L$25 -> 283685802
A5: Revenue | C5: ='P&L'!$D$3+$O$64+$O$65+$O$67+$O$68+$O$69 -> 6.0357889e+08 | E5: ='P&L'!$F$3+$O$64+$O$65+$O$67+$O$68+$O$69 -> 813192081 | G5: ='P&L'!$H$3+$Q$64+$Q$65+$Q$67+$Q$68+$Q$69 -> 712345078 | I5: ='P&L'!$J$3+$S$64+$S$65+$S$67+$S$68+$S$69 -> 436101037 | K5: ='P&L'!$L$3+$U$64+$U$65+$U$67+$U$68+$U$69 -> 262253962
A6: EBITDA (PBPT + D&A) | C6: =C7+'P&L'!D144+'P&L'!D148+'P&L'!D154 -> 1.4645576e+08 | E6: =E7+'P&L'!F144+'P&L'!F148+'P&L'!F154 -> 165159168 | G6: =G7+'P&L'!H144+'P&L'!H148+'P&L'!H154 -> 143168520 | I6: =I7+'P&L'!J144+'P&L'!J148+'P&L'!J154 -> 99124697 | K6: =K7+'P&L'!L144+'P&L'!L148+'P&L'!L154 -> 81530017
A7: PBPT (EBIT) | C7: ='P&L'!$D$24 -> 1.272089e+08 | E7: ='P&L'!$F$24 -> 146938167 | G7: ='P&L'!$H$24 -> 126816775 | I7: ='P&L'!$J$24 -> 85511699 | K7: ='P&L'!$L$24 -> 70115016
A8: EBT | C8: ='P&L'!$D$26 -> 1.0844157e+08 | E8: ='P&L'!$F$26 -> 120334380 | G8: ='P&L'!$H$26 -> 113550996 | I8: ='P&L'!$J$26 -> 77029938 | K8: ='P&L'!$L$26 -> 62027911
A9: Net Income | C9: ='P&L'!$D$33 -> 49883121 | E9: ='P&L'!$F$33 -> 57804659 | G9: ='P&L'!$H$33 -> 57757416 | I9: ='P&L'!$J$33 -> 34398330 | K9: ='P&L'!$L$33 -> 35506873
A10: Shares Outstanding | C10: ='P&L'!D35 -> 1466852 | E10: ='P&L'!F35 -> 1466852 | G10: ='P&L'!H35 -> 1466852 | I10: ='P&L'!J35 -> 1466852 | K10: ='P&L'!L35 -> 1466852
A11: EPS | C11: ='P&L'!D36 -> 33.866535 | E11: ='P&L'!F36 -> 39.85 | G11: ='P&L'!H36 -> 39.32 | I11: ='P&L'!J36 -> 23.23 | K11: ='P&L'!L36 -> 23.88
A12: Book Value per share | C12: =C4/C10 -> 307.77304 | E12: =E4/E10 -> 280.05422 | G12: =G4/G10 -> 249.528 | I12: =I4/I10 -> 194.3085 | K12: =K4/K10 -> 193.3977
A13: Sales per share | C13: =C5/C10 -> 411.47907 | E13: =E5/E10 -> 554.37909 | G13: =G5/G10 -> 485.62846 | I13: =I5/I10 -> 297.30405 | K13: =K5/K10 -> 178.78693
A14: Cash Dividend per share | C14: ='P&L'!D37 -> 10.953909 | E14: ='P&L'!F37 -> 16.25 | G14: ='P&L'!H37 -> 9.75 | I14: ='P&L'!J37 -> 6.75 | K14: ='P&L'!L37 -> 7.5
A15: PSX Filing Date of Annual Financial Statements | E15: 19-Feb-2025 02:00PM | G15: 23-Feb-2024 12:25AM | I15: 24-Feb-2023 12:39AM | K15: 24-Feb-2022 02:01PM
A16: Stock Price a day before Filing Date (Closing) | E16: 164.91 | G16: 112.95 | I16: 73.38 | K16: 121.41
A17: Stock Price on Filing Date (Closing) | E17: 162.46 | G17: 113.77 | I17: 69.56 | K17: 116.44
A18: Stock Price a week later from the Filing Date (Closing) | D18: 45742 | E18: 153.74 | F18: 45352 | G18: 117.06 | H18: 44988 | I18: 71.59 | J18: 44988 | K18: 115.16
A19: Stock Price a month later from the Filing Date (Closing) | D19: 45735 | E19: 154.02 | F19: 45376 | G19: 104.13 | H19: 45009 | I19: 72.5 | J19: 45009 | K19: 111.98
A20: Risk-free Rate (PIB Yield 10Y) | C20: ='Pakistan Investment Bonds'!I496 -> 0.1374048 | E20: ='Pakistan Investment Bonds'!I496 -> 0.1374048 | G20: ='Pakistan Investment Bonds'!I496 -> 0.1374048 | I20: ='Pakistan Investment Bonds'!I496 -> 0.1374048 | K20: ='Pakistan Investment Bonds'!I496 -> 0.1374048
A21: Beta | C21: ='Regression Monthly'!B18 -> 1.2900967 | E21: ='Regression Monthly'!B18 -> 1.2900967 | G21: ='Regression Monthly'!B18 -> 1.2900967 | I21: ='Regression Monthly'!B18 -> 1.2900967 | K21: ='Regression Monthly'!B18 -> 1.2900967
A22: Expected return on market (10-year CAGR) | C22: ='HBL Stock Price Monthly'!P9+0.05 -> 0.20742096 | E22: ='HBL Stock Price Monthly'!P9+0.05 -> 0.20742096 | G22: ='HBL Stock Price Monthly'!P9+0.05 -> 0.20742096 | I22: ='HBL Stock Price Monthly'!P9+0.05 -> 0.20742096 | K22: ='HBL Stock Price Monthly'!P9+0.05 -> 0.20742096
A23: Expected return on a security (CAPM) | C23: =C20+(C21*(C22-C20)) -> 0.22773242 | E23: =E20+(E21*(E22-E20)) -> 0.22773242 | G23: =G20+(G21*(G22-G20)) -> 0.22773242 | I23: =I20+(I21*(I22-I20)) -> 0.22773242 | K23: =K20+(K21*(K22-K20)) -> 0.22773242
A24: Retention ratio | C24: =(C11-C14)/C11 -> 0.67655654 | E24: =(E11-E14)/E11 -> 0.59222083 | G24: =(G11-G14)/G11 -> 0.75203459 | I24: =(I11-I14)/I11 -> 0.70942746 | K24: =(K11-K14)/K11 -> 0.68592965
A25: Sustainable Growth Rate | C25: =C24*C62 -> 0.074755102 | E25: =E24*E62 -> 0.083333208 | G25: =G24*G62 -> 0.11866974 | I25: =I24*I62 -> 0.085618429 | K25: =K24*K62 -> 0.085852788
A26: Return on Equity | C26: =C63 -> 0.1104935 | E26: =E63 -> 0.14071307 | G26: =G63 -> 0.15779824 | I26: =I63 -> 0.12068666 | K26: =K63 -> 0.12516267
A27: Effective Tax Rate | C27: ='P&L'!C27 -> 0.54 | E27: ='P&L'!E27 -> 0.51963305 | G27: ='P&L'!G27 -> 0.49135263 | I27: ='P&L'!I27 -> 0.55344207 | K27: ='P&L'!K27 -> 0.4275662
A29: Ratios
A30: P/E Ratio | C30: 25 | E30: 24 | G30: 23 | I30: 22 | K30: 21
A31: Stock Price a day before Filing Date (Closing) Previous Year Earnings | E31: =E16/G11 -> 4.1940488 | G31: =G16/I11 -> 4.8622471 | I31: =I16/K11 -> 3.0728643
A32: Stock Price on Filing Date (Closing) | E32: =E17/E$11 -> 4.076788 | G32: =G17/G$11 -> 2.8934385 | I32: =I17/I$11 -> 2.9944038 | K32: =K17/K$11 -> 4.8760469
A33: Stock Price a week later from the Filing Date (Closing) | E33: =E18/E$11 -> 3.8579674 | G33: =G18/G$11 -> 2.9771109 | I33: =I18/I$11 -> 3.0817908 | K33: =K18/K$11 -> 4.8224456
A34: Stock Price a month later from the Filing Date (Closing) | E34: =E19/E$11 -> 3.8649937 | G34: =G19/G$11 -> 2.6482706 | I34: =I19/I$11 -> 3.1209643 | K34: =K19/K$11 -> 4.6892797
A35: Justified Trailing ratio | C35: =((1-C24)*(1+C25))/(C23-C25) -> 2.2723794 | E35: =((1-E24)*(1+E25))/(E23-E25) -> 3.0593015 | G35: =((1-G24)*(1+G25))/(G23-G25) -> 2.5434126 | I35: =((1-I24)*(1+I25))/(I23-I25) -> 2.2197034 | K35: =((1-K24)*(1+K25))/(K23-K25) -> 2.4036866
A36: Justified Leading ratio | C36: =(1-C24)/(C23-C25) -> 2.114323 | E36: =(1-E24)/(E23-E25) -> 2.8239709 | G36: =(1-G24)/(G23-G25) -> 2.2736046 | I36: =(1-I24)/(I23-I25) -> 2.0446441 | K36: =(1-K24)/(K23-K25) -> 2.2136395
A38: P/B Ratio | C38: 25 | E38: 24 | G38: 23 | I38: 22 | K38: 21
A39: Stock Price a day before Filing Date (Closing) Previous Year Equity | E39: =E16/G12 -> 0.66088774 | G39: =G16/I12 -> 0.58129212 | I39: =I16/K12 -> 0.3794254
A40: Stock Price on Filing Date (Closing) | E40: =E17/E$12 -> 0.58010195 | G40: =G17/G$12 -> 0.45594081 | I40: =I17/I$12 -> 0.35798742 | K40: =K17/K$12 -> 0.60207541
A41: Stock Price a week later from the Filing Date (Closing) | E41: =E18/E$12 -> 0.54896512 | G41: =G18/G$12 -> 0.4691257 | I41: =I18/I$12 -> 0.36843473 | K41: =K18/K$12 -> 0.59545693
A42: Stock Price a month later from the Filing Date (Closing) | E42: =E19/E$12 -> 0.54996493 | G42: =G19/G$12 -> 0.41730787 | I42: =I19/I$12 -> 0.373118 | K42: =K19/K$12 -> 0.57901413
...

Sheet SOFP
A1: HABIB BANK LIMITED | D1: PKR | F1: PKR | H1: PKR | J1: PKR | L1: PKR | N1: PKR | P1: PKR
A2: CONSOLIDATED STATEMENT OF FINANCIAL POSITION | D2: 25 Forecast | F2: 24 | H2: 23 | J2: 22 | L2: 21 | N2: 20 | P2: 19
A3: ASSETS
A4: Cash and balances with treasury banks | D4: =D$19*D82 -> 4.2133749e+08 | F4: 460194916 | H4: 547528581 | J4: 296015386 | L4: 441252246 | N4: 375280120 | P4: 367593717
A5: Balances with other banks | D5: =D$19*D81 -> 72808358 | F5: 51324612 | H5: 56603548 | J5: 41513022 | L5: 64438075 | N5: 56533829 | P5: 41248554
A6: Lendings to financial institutions | D6: =D$19*D80 -> 1.5880951e+08 | F6: 84293922 | H6: 88598160 | J6: 254593287 | L6: 93742432 | N6: 30154193 | P6: 45303199
A7: Investments | D7: =D$19*D78 -> 2.8076679e+09 | F7: 2528200439 | H7: 2562299087 | J7: 1948801042 | L7: 1948955978 | N7: 1948576822 | P7: 1379607379
A8: Advances | D8: ='National Advances'!C25 -> 2.7902661e+09 | F8: 2435434872 | H8: 1861344592 | J8: 1782497923 | L8: 1507047097 | N8: 1223510222 | P8: 1166956994
A9: Property and equipment | C9: =AVERAGE(E9,G9,I9,K9,M9) -> 0.16000242 | D9: =F9*(1+C9) -> 1.5175752e+08 | E9: =F9/H9-1 -> 0.11587756 | F9: 130825175 | G9: =H9/J9-1 -> 0.40950059 | H9: 117239722 | I9: =J9/L9-1 -> 0.17068008 | J9: =105996430-J10 -> 83178200 | K9: =L9/N9-1 -> -0.017739496 | L9: =90872737-L10 -> 71051179 | M9: =N9/P9-1 -> 0.12169335 | N9: =89190210-N10 -> 72334354 | P9: =80462410-P10 -> 64486746
A10: Right-of-use assets | C10: =AVERAGE(E10,G10,I10,K10,M10) -> 0.11487619 | D10: =F10*(1+C10) -> 30556549 | E10: =F10/H10-1 -> 0.11167323 | F10: 27408020 | G10: =H10/J10-1 -> 0.080484551 | H10: 24654745 | I10: =J10/L10-1 -> 0.15118247 | J10: 22818230 | K10: =L10/N10-1 -> 0.17594491 | L10: 19821558 | M10: =N10/P10-1 -> 0.055095801 | N10: 16855856 | P10: 15975664
A11: Intangible assets | C11: =AVERAGE(E11,G11,I11,K11,M11) -> 0.22882223 | D11: =F11*(1+C11) -> 30534309 | E11: =F11/H11-1 -> 0.09365498 | F11: 24848435 | G11: =H11/J11-1 -> 0.23332409 | H11: 22720543 | I11: =J11/L11-1 -> 0.45855164 | J11: 18422200 | K11: =L11/N11-1 -> 0.21296654 | L11: 12630475 | M11: =N11/P11-1 -> 0.1456139 | N11: 10412880 | P11: 9089345
A12: Deferred tax assets | D12: =F12 -> 0 | F12: 0 | H12: 480873 | J12: 5797045 | N12: 0 | P12: 0
A13: Other assets | C13: =AVERAGE(E13,G13,I13,K13,M13) -> 0.19758332 | D13: =F13*(1+C13) -> 3.7434357e+08 | E13: =F13/H13-1 -> 0.23609776 | F13: 312582486 | G13: =H13/J13-1 -> 0.42631825 | H13: 252878451 | I13: =J13/L13-1 -> 0.17627441 | J13: 177294549 | K13: =L13/N13-1 -> 0.30606211 | L13: 150725500 | M13: =N13/P13-1 -> -0.15683592 | N13: 115404542 | P13: 136870799
A14: Total Assets | D14: =SUM(D4:D13) -> 6.8380813e+09 | F14: 6055112877 | H14: 5,534,348,303 | J14: 4638806111 | L14: 4317468145 | N14: 3849062818 | P14: 3227132397
A16: LIABILITIES
A17: Bills payable | C17: =AVERAGE(E17,G17,I17,K17,M17) -> 0.085733639 | D17: =(D$24-SUM(D$19:D$23))*C17 -> 82201034 | E17: =F17/(F$18+F$17) -> 0.10412291 | F17: 96104151 | G17: =H17/(H$18+H$17) -> 0.07213295 | H17: 51700823 | I17: =J17/(J$18+J$17) -> 0.081792682 | J17: 52001577 | K17: =L17/(L$18+L$17) -> 0.091989853 | L17: 44196984 | M17: =N17/(N$18+N$17) -> 0.078629796 | N17: 46434199 | O17: =P17/(P$18+P$17) -> 0.072061216 | P17: 29681108
A18: Borrowings | C18: =AVERAGE(E18,G18,I18,K18,M18) -> 0.91426636 | D18: =(D$24-SUM(D$19:D$23))*C18 -> 8.7659455e+08 | E18: =F18/(F$18+F$17) -> 0.89587709 | F18: 826883400 | G18: =H18/(H$18+H$17) -> 0.92786705 | H18: 665042679 | I18: =J18/(J$18+J$17) -> 0.91820732 | J18: 583771399 | K18: =L18/(L$18+L$17) -> 0.90801015 | L18: 436258005 | M18: =N18/(N$18+N$17) -> 0.9213702 | N18: 544107826 | O18: =P18/(P$18+P$17) -> 0.92793878 | P18: 382206306
A19: Deposits and other accounts | D19: ='National Deposits'!C50 -> 5.0136926e+09 | F19: 4370370642 | H19: 4142351836 | J19: 3469342252 | L19: 3381998398 | N19: 2830371390 | P19: 2437597169
A20: Lease liabilities | C20: =AVERAGE(E20,G20,I20) -> 0.17209923 | D20: =F20*(1+C20) -> 42042298 | E20: =F20/H20-1 -> 0.17642661 | F20: 35869231 | G20: =H20/J20-1 -> 0.12594434 | H20: 30489986 | I20: =J20/L20-1 -> 0.21392674 | J20: 27079479 | L20: 22307342
A21: Subordinated debt | C21: =AVERAGE(E21,G21,I21,K21,M21) -> 0.03131813 | D21: =F21*(1+C21) -> 21012076 | E21: =F21/H21-1 -> 0.034265699 | F21: 20374000 | G21: =H21/J21-1 -> 0.043710925 | H21: 19699000 | I21: =J21/L21-1 -> 0.52529497 | J21: 18874000 | K21: =L21/N21-1 -> -0.44650206 | L21: 12374000 | M21: =N21/P21-1 -> -0.00017889088 | N21: 22356000 | P21: 22360000
A22: Deferred tax liabilities | D22: =F22 -> 7995007 | F22: 7995007 | L22: 5082602 | N22: 10387859 | P22: 6189687
A23: Other liabilities | C23: =AVERAGE(E23,G23,I23,K23,M23) -> 0.19659674 | D23: =F23*(1+C23) -> 3.4308625e+08 | E23: =F23/H23-1 -> 0.10683551 | F23: 286718352 | G23: =H23/J23-1 -> 0.27786583 | H23: 259043326 | I23: =J23/L23-1 -> 0.54080167 | J23: =229795069-J20 -> 202715590 | K23: =L23/N23-1 -> 0.012737366 | L23: =153872354-L20 -> 131565012 | M23: =N23/P23-1 -> 0.044743333 | N23: 129910297 | P23: 124346615
A24: Total Liabiliatied | D24: =D14-D25 -> 6.3866238e+09 | F24: 5644314783 | H24: 5168327650 | J24: 4353784297 | L24: 4033782343 | N24: 3583567571 | P24: 3002380885
A25: NET ASSETS | C25: =AVERAGE(E25,G25,I25,K25,M25) -> 0.066021079 | D25: =D14*C25 -> 4.5145751e+08 | E25: =F25/F14 -> 0.067843177 | F25: 410798094 | G25: =H25/H14 -> 0.06613618 | H25: 366020653 | I25: =J25/J14 -> 0.061442925 | J25: 285021814 | K25: =L25/L14 -> 0.065706519 | L25: 283685802 | M25: =N25/N14 -> 0.068976595 | N25: 265495247 | O25: =P25/P14 -> 0.069644342 | P25: 224751512
A27: Shareholders' equity
A28: Share capital | D28: =F28 -> 14668525 | F28: 14668525 | H28: 14668525 | J28: 14668525 | L28: 14668525 | N28: 14668525 | P28: 14668525
A29: Reserves | C29: =AVERAGE(E29,G29,I29,K29,M29) -> 0.083814063 | D29: =F29*(1+C29) -> 1.065421e+08 | E29: =F29/H29-1 -> -0.024822361 | F29: 98302935 | G29: =H29/J29-1 -> 0.14849752 | H29: 100805157 | I29: =J29/L29-1 -> 0.078596279 | J29: 87771332 | K29: =L29/N29-1 -> 0.12924275 | L29: 81375519 | M29: =N29/P29-1 -> 0.087556131 | N29: 72062025 | P29: 66260511
A30: Surplus on revaluation of assets - net of tax | D30: =F30 -> 57370781 | F30: 57370781 | H30: 25857323 | J30: 1235369 | L30: 25159371 | N30: 36004914 | P30: 24875383
A31: Unappropriated profit | D31: =D34-SUM(D28:D30) -> 2.728761e+08 | F31: 238813471 | H31: 221883756 | J31: 178467639 | L31: 158441418 | N31: 138208223 | P31: 114550097
A32: Total equity attributable to the equity holders of the Bank | C32: =AVERAGE(E32,G32,I32,K32,M32,O32) -> 0.98788054 | D32: =D34*C32 -> 4.4598608e+08 | E32: =F32/F$34 -> 0.99600197 | F32: 409155712 | G32: =H32/H$34 -> 0.99233406 | H32: 363214761 | I32: =J32/J$34 -> 0.9898992 | J32: 282142865 | K32: =L32/L$34 -> 0.98575548 | L32: 279644833 | M32: =N32/N$34 -> 0.98285634 | N32: 260943687 | O32: =P32/P$34 -> 0.98043619 | P32: 220354516
A33: Non-controlling interest | C33: =AVERAGE(E33,G33,I33,K33,M33,O33) -> 0.01211946 | D33: =D34*C33 -> 5471421.3 | E33: =F33/F$34 -> 0.0039980273 | F33: 1642382 | G33: =H33/H$34 -> 0.007665939 | H33: 2805892 | I33: =J33/J$34 -> 0.010100802 | J33: 2878949 | K33: =L33/L$34 -> 0.014244523 | L33: 4040969 | M33: =N33/N$34 -> 0.017143659 | N33: 4551560 | O33: =P33/P$34 -> 0.019563811 | P33: 4396996
D34: =D25 -> 4.5145751e+08 | F34: 410798094 | H34: 366020653 | J34: 285,021,814 | L34: 283685802 | N34: 265495247 | P34: 224751512
Q36: Adjusted Revaluation Surplus
A37: 1
A38: Investments:
A39: Market Treasury Bills | C39: 0.215 | D39: =D$52*C39 -> 6.0364859e+08 | E39: =F39/F$52 -> 0.1766476 | F39: 446600531 | G39: =H39/H$52 -> 0.1653845 | H39: 423764549 | I39: =J39/J$52 -> 0.17308731 | J39: 337312735 | K39: =L39/L$52 -> 0.20097912 | L39: 391699451 | M39: =N39/N$52 -> 0.3245299 | N39: 632371432 | O39: =P39/P$52 -> 0.43886911 | P39: 605467062
A40: Pakistan Investment Bonds | C40: 0.52 | D40: =D$52*C40 -> 1.4599873e+09 | E40: =F40/F$52 -> 0.54084158 | F40: 1367355920 | G40: =H40/H$52 -> 0.60756457 | H40: 1556762138 | I40: =J40/J$52 -> 0.61129566 | J40: 1191293622 | K40: =L40/L$52 -> 0.60499795 | L40: 1179114373 | M40: =N40/N$52 -> 0.53254389 | N40: 1037702672 | O40: =P40/P$52 -> 0.451731 | P40: 623211426
A41: Ijarah Sukuk | C41: =E41 -> 0.13503515 | D41: =D$52*C41 -> 3.7913386e+08 | E41: =F41/F$52 -> 0.13503515 | F41: 341395936 | G41: =H41/H$52 -> 0.08635633 | H41: 221270745 | I41: =J41/J$52 -> 0.062904179 | J41: 122587729 | K41: =L41/L$52 -> 0.061099803 | L41: 119080826 | M41: =N41/N$52 -> 0.034566741 | N41: 67355950 | O41: =P41/P$52 -> 0.0033495566 | P41: 4621073
A42: Government of Pakistan US Dollar Bonds | C42: =(E42+G42+I42+K42+M42+O42)/6 -> 0.0065103977 | D42: =D$52*C42 -> 18279034 | E42: =F42/F$52 -> 0.0052037765 | F42: 13156190 | G42: =H42/H$52 -> 0.0090979765 | H42: 23311737 | I42: =J42/J$52 -> 0.0068489629 | J42: 13347266 | K42: =L42/L$52 -> 0.0084503094 | L42: 16469281 | M42: =N42/N$52 -> 0.0058492972 | N42: 11397805 | O42: =P42/P$52 -> 0.0036120639 | P42: 4983230
A43: Other Federal Government securities | C43: =D43/D44 -> 0.0031949759 | D43: =D44-SUM(D39:D42) -> 7888194.1 | E43: =F43/F$52 -> 0.0010207755 | F43: 2580725 | G43: =H43/H$52 -> 0.0021633532 | H43: 5543158 | I43: =J43/J$52 -> 0.0024045862 | J43: 4686060 | K43: =L43/L$52 -> 0.0060597161 | L43: 11810120 | M43: =N43/N$52 -> 0.005811697 | N43: 11324538 | O43: =P43/P$52 -> 0.0078239651 | P43: 10794000
...

Sheet P&L
A1: HABIB BANK LIMITED | D1: PKR | F1: PKR | H1: PKR | J1: PKR | L1: PKR | N1: PKR | P1: PKR
A2: CONSOLIDATED STATEMENT OF PROFIT AND LOSS ACCOUNT | D2: 25 Forecast | F2: 24 | H2: 23 | J2: 22 | L2: 21 | N2: 20 | P2: 19
A3: Mark-up / return / profit / interest earned | D3: =D45 -> 6.0357889e+08 | F3: 813192081 | H3: 712345078 | J3: 436101037 | L3: 262253962 | N3: 271237258 | P3: 258113896
A4: Mark-up / return / profit / interest expensed | D4: ='National Deposits'!C95 -> 3.3507174e+08 | F4: 567569845 | H4: 470212037 | J4: 270538340 | L4: 130834913 | N4: 141132940 | P4: 156790596
A5: Net mark-up / return / profit / interest income | D5: =D3-D4 -> 2.6850716e+08 | F5: 245622236 | H5: 242133041 | J5: 165562697 | L5: 131419049 | N5: 130104318 | P5: 101323300
A7: Non mark-up / interest income
A8: Fee and commission income | C8: {=AVERAGE( _xlfn._xlws.FILTER( CHOOSE({1,2,3,4,5}, E8, G8, I8, K8, M8), ISNUMBER(CHOOSE({1,2,3,4,5}, E8, G8, I8, K8, M8)) ) )} -> 0.20485125 | D8: =F8*(1+C8) -> 59667705 | E8: =F8/H8-1 -> 0.17213412 | F8: 49522881 | G8: =H8/J8-1 -> 0.3408439 | H8: 42250183 | I8: =J8/L8-1 -> 0.23892986 | J8: 31510143 | K8: =L8/N8-1 -> 0.35314472 | L8: 25433355 | M8: =N8/P8-1 -> -0.080796363 | N8: 18795739 | P8: 20447851
A9: Dividend income | C9: {=AVERAGE( _xlfn._xlws.FILTER( CHOOSE({1,2,3,4,5}, E9, G9, I9, K9, M9), ISNUMBER(CHOOSE({1,2,3,4,5}, E9, G9, I9, K9, M9)) ) )} -> 0.44355945 | D9: =F9*(1+C9) -> 4449656.5 | E9: =F9/H9-1 -> 0.33961822 | F9: 3082420 | G9: =H9/J9-1 -> 0.52519118 | H9: 2300969 | I9: =J9/L9-1 -> 0.65101136 | J9: 1508643 | K9: =L9/N9-1 -> 0.8674911 | L9: 913769 | M9: =N9/P9-1 -> -0.16551463 | N9: 489303 | P9: 586353
A10: Share of profit of associates and joint venture | C10: {=AVERAGE( _xlfn._xlws.FILTER( CHOOSE({1,2,3,4,5}, E10, G10, I10, K10, M10), ISNUMBER(CHOOSE({1,2,3,4,5}, E10, G10, I10, K10, M10)) ) )} -> 0.086358077 | D10: =F10*(1+C10) -> 5174323.5 | E10: =F10/H10-1 -> 0.076945166 | F10: 4763000 | G10: =H10/J10-1 -> 0.46038093 | H10: 4422695 | I10: =J10/L10-1 -> 0.17127895 | J10: 3028453 | K10: =L10/N10-1 -> -0.1273991 | L10: 2585595 | M10: =N10/P10-1 -> -0.14941556 | N10: 2963090 | P10: 3483593
A11: Foreign exchange income | C11: {=AVERAGE( _xlfn._xlws.FILTER( CHOOSE({1,2,3,4,5}, E11, G11, I11, K11, M11), ISNUMBER(CHOOSE({1,2,3,4,5}, E11, G11, I11, K11, M11)) ) )} -> -0.58980423 | D11: =F11*(1+C11) -> 3239123.2 | E11: =F11/H11-1 -> 0.71504793 | F11: 7896530 | G11: =H11/J11-1 -> -0.97672113 | H11: 4604262 | I11: =J11/L11-1 -> #DIV/0! | J11: =F50+F51+F52 -> 1.9778719e+08 | K11: =L11/N11-1 -> -1 | L11: =G50+G51+G52 -> 0 | M11: =N11/P11-1 -> -1.0975437 | N11: -161688 | P11: 1657595
A12: Income / (loss) from derivatives | C12: {=AVERAGE( _xlfn._xlws.FILTER( CHOOSE({1,2,3,4,5}, E12, G12, I12, K12, M12), ISNUMBER(CHOOSE({1,2,3,4,5}, E12, G12, I12, K12, M12)) ) )} -> 0.052947187 | D12: =F12*(1+C12) -> 6076944.6 | E12: =F12/H12-1 -> -4.7344177 | F12: 5771367 | G12: =H12/J12-1 -> -0.40970076 | H12: -1545453 | I12: =J12/L12-1 -> 13.377335 | J12: -2618084 | K12: =L12/N12-1 -> -1.1689307 | L12: -182098 | M12: =N12/P12-1 -> -6.7995502 | N12: 1077945 | P12: -185867
A13: Gain on securities - net | D13: {=AVERAGE( _xlfn._xlws.FILTER( CHOOSE({1,2,3,4,5}, F13, H13, J13, L13, N13), ISNUMBER(CHOOSE({1,2,3,4,5}, F13, H13, J13, L13, N13)) ) )} -> 4070829.8 | F13: 10462735 | H13: 945981 | J13: 866175 | L13: 1024384 | N13: 7054874 | P13: -2657256
A14: Other income | D14: {=AVERAGE( _xlfn._xlws.FILTER( CHOOSE({1,2,3,4,5}, F14, H14, J14, L14, N14), ISNUMBER(CHOOSE({1,2,3,4,5}, F14, H14, J14, L14, N14)) ) )} -> 4301203.8 | F14: 15013202 | H14: 4472468 | J14: 488991 | L14: 1155761 | N14: 375597 | P14: 829310
A15: Total non mark-up / interest income | D15: =SUM(D8:D14) -> 86979786 | F15: 96512135 | H15: 57451105 | J15: 46731737 | L15: 36311360 | N15: 30594860 | P15: 24161579
A16: Total income | D16: =D5+D15 -> 3.5548694e+08 | F16: 342134371 | H16: 299584146 | J16: 212294434 | L16: 167730409 | N16: 160699178 | P16: 125484879
A18: Non mark-up / interest expenses
A19: Operating expenses | C19: {=AVERAGE( _xlfn._xlws.FILTER( CHOOSE({1,2,3,4,5}, E19, G19, I19, K19, M19), ISNUMBER(CHOOSE({1,2,3,4,5}, E19, G19, I19, K19, M19)) ) )} -> 0.16711678 | D19: =F19*(1+C19) -> 2.2464016e+08 | E19: =F19/H19-1 -> 0.13133686 | F19: 192474447 | G19: =H19/J19-1 -> 0.36314049 | H19: 170130095 | I19: =J19/L19-1 -> 0.30299625 | J19: 124807455 | K19: =L19/N19-1 -> 0.018789555 | L19: 95784969 | M19: =N19/P19-1 -> 0.019320771 | N19: 94018405 | P19: 92236328
A20: Workers' Welfare Fund | C20: {=AVERAGE( _xlfn._xlws.FILTER( CHOOSE({1,2,3,4,5}, E20, G20, I20, K20, M20), ISNUMBER(CHOOSE({1,2,3,4,5}, E20, G20, I20, K20, M20)) ) )} -> 0.36367536 | D20: =F20*(1+C20) -> 3224542.7 | E20: =F20/H20-1 -> 0.03604836 | F20: 2364597 | G20: =H20/J20-1 -> 0.5228756 | H20: 2282323 | I20: =J20/L20-1 -> 0.17708325 | J20: 1498693 | K20: =L20/N20-1 -> 0.14732953 | L20: 1273226 | M20: =N20/P20-1 -> 0.93504007 | N20: 1109730 | P20: 573492
A21: Other charges | D21: {=AVERAGE( _xlfn._xlws.FILTER( CHOOSE({1,2,3,4,5}, F21, H21, J21, L21, N21), ISNUMBER(CHOOSE({1,2,3,4,5}, F21, H21, J21, L21, N21)) ) )} -> 413338.2 | F21: 357160 | H21: 354953 | J21: 476587 | L21: 557198 | N21: 320793 | P21: 480056
A22: Total non mark-up / interest expenses | D22: =SUM(D19:D21) -> 2.2827804e+08 | F22: 195196204 | H22: 172767371 | J22: 126782735 | L22: 97615393 | N22: 95448928 | P22: 93289876
A24: Profit before credit loss allowance and taxation | D24: =D16-D22 -> 1.272089e+08 | F24: 146938167 | H24: 126816775 | J24: 85511699 | L24: 70115016 | N24: 65250250 | P24: 32195003
A25: Credit loss allowance and write offs - net | D25: ='Credit Loss Allowance'!D15 -> 18767336 | F25: 26603787 | H25: 13265779 | J25: 8481761 | L25: 8087105 | N25: 12219614 | P25: 3314081
A26: Profit before taxation | D26: =D24-D25 -> 1.0844157e+08 | F26: 120334380 | H26: 113550996 | J26: 77029938 | L26: 62027911 | N26: 53030636 | P26: 28880922
A27: Taxation | C27: 0.54 | D27: =D26*C27 -> 58558446 | E27: =F27/F26 -> 0.51963305 | F27: 62529721 | G27: =H27/H26 -> 0.49135263 | H27: 55793580 | I27: =J27/J26 -> 0.55344207 | J27: 42631608 | K27: =L27/L26 -> 0.4275662 | L27: 26521038 | M27: =N27/N26 -> 0.41706622 | N27: 22117287 | P27: 13381127
A28: Profit after taxation | D28: =D26-D27 -> 49883121 | F28: 57804659 | H28: 57757416 | J28: 34398330 | L28: 35506873 | N28: 30913349 | P28: 15499795
A30: Attributable to:
A31: Equity holders of the Bank | C31: =AVERAGE(E31,G31,I31,K31,M31,O31) -> 0.99587183 | D31: =D$28*C31 -> 49677195 | E31: =F31/F$33 -> 1.0112986 | F31: 58457771 | G31: =H31/H$33 -> 0.99859107 | H31: 57676040 | I31: =J31/J$33 -> 0.99045759 | J31: 34070087 | K31: =L31/L$33 -> 0.98634011 | L31: 35021853 | M31: =N31/N$33 -> 0.99931816 | N31: 30892271 | O31: =P31/P$33 -> 0.98922547 | P31: 15332792
A32: Non-controlling interest | C32: =AVERAGE(E32,G32,I32,K32,M32,O32) -> 0.0041281658 | D32: =D$28*C32 -> 205925.79 | E32: =F32/F$33 -> -0.011298605 | F32: -653112 | G32: =H32/H$33 -> 0.0014089273 | H32: 81376 | I32: =J32/J$33 -> 0.0095424109 | J32: 328243 | K32: =L32/L$33 -> 0.013659891 | L32: 485020 | M32: =N32/N$33 -> 0.00068184136 | N32: 21078 | O32: =P32/P$33 -> 0.01077453 | P32: 167003
A33: Profit after taxation | D33: =SUM(D31:D32) -> 49883121 | F33: 57804659 | H33: 57757416 | J33: 34398330 | L33: 35506873 | N33: 30913349 | P33: 15499795
A35: Share Outstanding | D35: =F35 -> 1466852 | F35: 1466852 | H35: 1466852 | J35: 1466852 | L35: 1466852 | N35: 1466852 | P35: 1466852
A36: Basic and diluted earnings per share | D36: =D31/D35 -> 33.866535 | F36: 39.85 | H36: 39.32 | J36: 23.23 | L36: 23.88 | N36: 21.06 | P36: 10.45
A37: Cash Dividend per share | D37: =D36*D38 -> 10.953909 | F37: 16.25 | H37: 9.75 | J37: 6.75 | L37: 7.5 | N37: 4.25 | P37: 5
A38: Dividend/Earning | D38: =AVERAGE(F38,H38,J38,L38,N38,P38) -> 0.32344346 | F38: =F37/F36 -> 0.40777917 | H38: =H37/H36 -> 0.24796541 | J38: =J37/J36 -> 0.29057254 | L38: =L37/L36 -> 0.31407035 | N38: =N37/N36 -> 0.20180437 | P38: =P37/P36 -> 0.4784689
A39: Profit Retained | D39: =D33*(1-D38) -> 33748752 | F39: =F33*(1-F38) -> 34233123 | H39: =H33*(1-H38) -> 43435575 | J39: =J33*(1-J38) -> 24403120 | L39: =L33*(1-L38) -> 24355217 | N39: =N33*(1-N38) -> 24674900 | P39: =P33*(1-P38) -> 8083625.1
A41: Loans and advances | D41: =D58 -> 2.6124776e+08 | F41: 312318372 | H41: 300113714 | J41: 192939922 | L41: 111742121 | N41: 116793732 | P41: 132394180
A42: Investments | D42: =D103 -> 3.1030041e+08 | F42: 472523900 | H42: 370788429 | J42: 226000345 | L42: 143232732 | N42: 148742484 | P42: 110142418
A43: Lendings to financial institutions | D43: =D74 -> 17469046 | F43: 15222196 | H43: 30364394 | J43: 15354518 | L43: 6849788 | N43: 5027219 | P43: 14180501
A44: Balances with banks | D44: =D78 -> 14561672 | F44: 13127613 | H44: 11078541 | J44: 1806252 | L44: 429321 | N44: 673823 | P44: 1396797
A45: Gross Interest Income | D45: =SUM(D41:D44) -> 6.0357889e+08 | F45: =SUM(F41:F44) -> 813192081 | H45: =SUM(H41:H44) -> 712345078 | J45: 436101037 | L45: 262253962 | N45: 271237258 | P45: 258113896
C50: Estimated Spread
...

Sheet CF
A1: HABIB BANK LIMITED | K1: PKR | M1: PKR | O1: PKR | Q1: PKR | S1: PKR
A2: CONSOLIDATED CASH FLOW STATEMENT | K2: 25 Forecast | M2: 24 | O2: 23 | Q2: 22 | S2: 21
A3: Profit before taxation | K3: ='P&L'!D26 -> 1.0844157e+08 | M3: 120334380 | O3: 113550996 | Q3: 77029938 | S3: 62027911
A4: Dividend income | K4: =-'P&L'!D9 -> -4449656.5 | M4: -3082420 | O4: -2300969 | Q4: -1508643 | S4: -913769
A5: Share of profit of associates and joint venture | C5: USD | E5: USD | G5: USD | I5: USD | K5: =-'P&L'!D10 -> -5174323.5 | M5: -4763000 | O5: -4422695 | Q5: -3028453 | S5: -2585595
A6: Mark-up expensed on subordinated debt | C6: 24 | E6: 23 | G6: 22 | I6: 21 | K6: ='P&L'!D138 -> 3587276.5 | M6: 4096181 | O6: 4281784 | Q6: 1891880 | S6: 1239075
C7: 432003 | E7: 407650 | K7: =SUM(K4:K6) -> -6036703.6 | M7: -3749239 | O7: -2441880 | Q7: -2645216 | S7: -2260289
C8: -11066 | E8: -8261 | K8: =K3-K7 -> 1.1447827e+08 | M8: 116585141 | O8: 111109116 | Q8: 74384722 | S8: 59767622
C9: -17099 | E9: -15878
A10: Non-Cash Expenses | C10: 14705 | E10: 15372
A11: Depreciation | C11: -13460 | E11: -8767 | K11: ='P&L'!D144 -> 11775229 | M11: 10957614 | O11: 9680335 | Q11: 7782494 | S11: 6969192
A12: Amortisation | C12: 418543 | E12: 398883 | K12: ='P&L'!D154 -> 1948774.3 | M12: 2738087 | O12: 2246980 | Q12: 1852350 | S12: 1061035
A13: Depreciation on right-of-use assets | K13: ='P&L'!D148 -> 5522854.6 | M13: 4525300 | O13: 4426688 | Q13: 3978154 | S13: 3384774
A14: Provision for / (reversal of) diminution in value of investments | K14: 0 | Q14: 3851708 | S14: -1258723
A15: Mark-up expensed on lease liability against right-of-use assets | C15: 39338 | E15: 34753 | K15: ='National Deposits'!C94 -> 3985416 | M15: 3551598 | O15: 3345591 | Q15: 3145165 | S15: 3252794
A16: Reversal of credit loss allowance against investments | C16: 9830 | E16: 8067 | K16: 0 | M16: -1730634 | O16: -184104
A17: Provisions / credit loss allowance against loans and advances | C17: 16246 | E17: 15892 | K17: ='Credit Loss Allowance'!D38 -> 16595894 | M17: 20568188 | O17: 13469201 | Q17: 5943661 | S17: 7645044
A18: Reversal of credit loss allowance against lendings to financial institutions | K18: ='Credit Loss Allowance'!D6 -> -170.71612 | M18: -1210 | O18: -
A19: Provision / credit loss allowance against other assets | C19: 12750 | E19: 12011 | K19: ='Credit Loss Allowance'!D7 -> 1219618.4 | M19: 2340528 | O19: 1140717 | Q19: 624244 | S19: 190136
A20: Charge / (reversal) of credit loss allowance against off-balance sheet obligations | C20: -6213 | E20: -661 | K20: ='Credit Loss Allowance'!D8 -> 867247.06 | M20: 4606306 | O20: -93890 | Q20: -1331585 | S20: 1540508
A21: Unrealised gain on securities designated at fair value through profit and loss (FVTPL) | C21: 73840 | E21: 48355 | K21: 0 | M21: -1263203 | O21: -
A22: Unrealised gain on held-for-trading securities | C22: -4 | E22: - | K22: 0 | M22: - | O22: -280323 | Q22: 84390 | S22: -67246
A23: Gain on derecognition of joint venture | C23: 8403 | E23: 4095 | K23: 0 | M23: - | O23: -3731399 | Q23: 0 | S23: 0
A24: Exchange loss / (gain) on goodwill | C24: 16537 | E24: -337 | K24: 0 | M24: 109740 | O24: -1055507 | Q24: -429394 | S24: -244750
A25: Exchange gain realised on partial repatriation of branch capital - net of tax | C25: -4535 | E25: - | K25: 0 | S25: -246489
A26: Exchange gain realised on liquidation of subsidiary - net of tax | C26: - | E26: -1006 | K26: 0 | S26: -1369
A27: Gain on sale of property and equipment - net | C27: - | E27: -13396 | K27: 0 | M27: -156538 | O27: -48681 | Q27: -42024 | S27: -79639
A28: Gain realised on closure / sale of the Bank's branches | C28: 394 | E28: -3789 | K28: 0 | M28: -14254667 | O28: - | Q28: 0 | S28: -16000
A29: Workers' Welfare Fund | K29: ='P&L'!D20 -> 3224542.7 | M29: 2364597 | O29: 2282323 | Q29: 1498693 | S29: 1273226
A30: Non-Cash Expenses | K30: =SUM(K11:K29) -> 45139406 | M30: 34355706 | O30: 31197931 | Q30: 26957856 | S30: 23402493
A31: Profit before taxation adjusted for non-cash expenses | C31: -562 | E31: -175 | K31: =K30+K8 -> 1.5961768e+08 | M31: 150940847 | O31: 142307047 | Q31: 101342578 | S31: 83170115
C32: -51175 | E32: -
A33: (Increase) / decrease in operating assets | C33: 8489 | E33: 8194
A34: Lendings to financial institutions | C34: 123338 | E34: 112003 | K34: =SOFP!F6-SOFP!D6 -> -74515589 | M34: 4296525 | O34: 165995127 | Q34: -160850855 | S34: -63588239
A35: Net investment in securities carried at FVTPL | C35: 541881 | E35: 510886 | K35: =SOFP!F135-SOFP!D135 -> -1.0111302e+08 | M35: 91405547 | O35: - | Q35: 0 | S35: 0
A36: Net investment in held-for-trading securities | K36: 0 | M36: - | O36: -178812226 | Q36: 142875183 | S36: -72978890
A37: Advances | K37: =SOFP!F8-SOFP!D8 -> -3.5483128e+08 | M37: -651100311 | O37: -92315870 | Q37: -281394487 | S37: -291181919
A38: Other assets (excluding advance taxation) | C38: 15425 | E38: 595926 | K38: =SOFP!F13-SOFP!D13 -> -61761087 | M38: 7476467 | O38: -83795260 | Q38: -31429797 | S38: -34306119
A39: (Increase) / decrease in operating assets | C39: 328148 | E39: - | K39: =SUM(K34:K38) -> -5.9222097e+08 | M39: -547921772 | O39: -188928229 | Q39: -330799956 | S39: -462055167
C40: - | E40: -641939
...

Sheet Capital Adequacy and Liquidity
A1: HABIB BANK LIMITED
A2: CAPITAL ADEQUACY AND LIQUIDITY DISCLOSURE | C2: PKR | E2: PKR | G2: PKR | I2: PKR
A3: On-balance sheet | C3: 24 | E3: 23 | G3: 22 | I3: 21
A4: Sovereigns | C4: 188007983 | E4: 220694114 | G4: 169188045 | I4: 134646975
A5: Public Sector Entities | C5: 40515867 | E5: 34860385 | G5: 34618570 | I5: 34638689
A6: Multilateral Development Banks | C6: 0 | E6: 0 | G6: 379658 | I6: 623184
A7: Banks | C7: 142832495 | E7: 88249491 | G7: 71698824 | I7: 99803166
A8: Corporates | C8: 584863243 | E8: 596497395 | G8: 603109959 | I8: 517129917
A9: Retail | C9: 307316054 | E9: 283150039 | G9: 261121134 | I9: 217681533
A10: Residential mortgages | C10: 17690609 | E10: 13106314 | G10: 8715744 | I10: 6979380
A11: Low Cost Housing | C11: 1781213 | E11: 1922030 | G11: 2025188 | I11: 518924
A12: Past due loans | C12: 8196097 | E12: 16220289 | G12: 12675228 | I12: 6979726
A13: Listed equity investments | C13: 5864302 | E13: 8571270 | G13: 6777298 | I13: 3750255
A14: Unlisted equity investments | C14: 581993 | E14: 7117404 | G14: 7141103 | I14: 7181663
... A18: On-balance sheet Assets | C18: 1581427836 | E18: 1516674571 | G18: 1401128779 | I18: 1196735096
A20: Off-balance sheet
A21: Non-market related | C21: 139947639 | E21: 121315175 | G21: 107895419 | I21: 125698401
A22: Market related | C22: 4449114 | E22: 3029974 | G22: 2816544 | I22: 6357655
A23: Off-balance sheet Assets | C23: 144396753 | E23: 124345149 | G23: 110711963 | I23: 132056056
A25: Market Risk
A26: Interest Rate Risk | C26: 73698487 | E26: 69778337 | G26: 32110088 | I26: 30729675
A27: Equity Position Risk | C27: 37264900 | E27: 17256000 | G27: 7623075 | I27: 16238275
A28: Foreign Exchange Risk | C28: 120495038 | E28: 110076688 | G28: 65484575 | I28: 69711838
A29: Market Risk | C29: 231458425 | E29: 197111025 | G29: 105217738 | I29: 116679788
A30: Operational Risk | C30: 388610901 | E30: 303760456 | G30: 266263405 | I30: 224085265
A31: Total Risk Weighted Assets | C31: 2345893915 | E31: 2141891201 | G31: 1883321885 | I31: 1669556205
A33: Capital Adequacy Ratio
A34: Total eligible regulatory capital held | C34: 415322248 | E34: 342825915 | G34: 279322811 | I34: 260917929
A35: Total risk weighted assets | C35: 2345893915 | E35: 2141891201 | G35: 1883321885 | I35: 1669556205
A36: Capital adequacy ratio | C36: 0.177 | E36: 0.1601 | G36: 0.1483 | I36: 0.1563
A38: Common Equity Tier I
A39: Fully Paid-up Capital | C39: 14668525 | E39: 14668525 | G39: 14668525 | I39: 14668525
A40: Balance in Share Premium Account - - | C40: 0 | E40: 0 | G40: 0 | I40: 0
A41: Reserve for issue of Bonus Shares - - | C41: 0 | E41: 0 | G41: 0 | I41: 0
A42: Discount on Issue of shares - - | C42: 0 | E42: 0 | G42: 0 | I42: 0
A43: General and Capital Reserves | C43: 98302935 | E43: 50500007 | G43: 46044309 | I43: 42549449
A44: Gain/(Losses) on derivatives held as Cash Flow Hedge - - | C44: 0 | E44: 0 | G44: 0 | I44: 0
A45: Unappropriated profit | C45: 246508577 | E45: 221883756 | G45: 178467639 | I45: 158441418
A46: Non-controlling interest arising from CET1 capital instruments issued to third parties | C46: 0 | E46: 0 | G46: 0 | I46: 0
A47: by consolidated banking subsidiaries (amount allowed in CET1 capital of the - - | C47: 0 | E47: 0 | G47: 0 | I47: 0
...

Sheet Credit Loss Allowance
A1: HABIB BANK LIMITED | D1: PKR | G1: PKR | J1: PKR | M1: PKR | P1: PKR | S1: PKR | V1: PKR
A2: CREDIT LOSS ALLOWANCE | D2: 25 Forecast | G2: 24 | J2: 23 | M2: 22 | P2: 21 | S2: 20 | V2: 19
A3: Reversal of credit loss allowance against investments | C3: {=AVERAGE( _xlfn._xlws.FILTER( CHOOSE({1,2,3,4,5}, F3, I3, L3, O3, R3), ISNUMBER(CHOOSE({1,2,3,4,5}, F3, I3, L3, O3, R3)) ) )} -> 0.038845386 | D3: =C3*D$15 -> 729024.41 | F3: =G3/G$15 -> -0.065052167 | G3: -1730634 | I3: =J3/J$15 -> -0.013878115 | J3: -184104 | L3: =M3/M$15 -> 0.45411654 | M3: 3851708 | O3: =P3/P$15 -> -0.15564569 | P3: -1258723 | R3: =S3/S$15 -> -0.025313647 | S3: -309323 | U3: =V3/V$15 -> 0.1668897 | V3: 553086
A4: Credit loss allowance against loans and advances | C4: {=AVERAGE( _xlfn._xlws.FILTER( CHOOSE({1,2,3,4,5}, F4, I4, L4, O4, R4), ISNUMBER(CHOOSE({1,2,3,4,5}, F4, I4, L4, O4, R4)) ) )} -> 0.88429675 | D4: =D38 -> 16595894 | F4: =G4/G$15 -> 0.77313008 | G4: 20568188 | I4: =J4/J$15 -> 1.0153343 | J4: 13469201 | L4: =M4/M$15 -> 0.7007579 | M4: 5943661 | O4: =P4/P$15 -> 0.94533755 | P4: 7645044 | R4: =S4/S$15 -> 0.98692389 | S4: 12059829 | U4: =V4/V$15 -> 1.0187135 | V4: 3376099
A5: Credit loss allowance against cash and cash equivalent | C5: {=AVERAGE( _xlfn._xlws.FILTER( CHOOSE({1,2,3,4,5}, F5, I5, L5, O5, R5), ISNUMBER(CHOOSE({1,2,3,4,5}, F5, I5, L5, O5, R5)) ) )} -> 5.7427914e-05 | D5: =C5*D$15 -> 1077.769 | F5: =G5/G$15 -> 0.00028713957 | G5: 7639 | I5: =J5/J$15 -> 0 | J5: 0 | L5: =M5/M$15 -> 0 | M5: 0 | O5: =P5/P$15 -> 0 | P5: 0 | R5: =S5/S$15 -> 0 | S5: 0 | U5: =V5/V$15 -> 0 | V5: 0
A6: Reversal of credit loss allowance against lendings to financial institutions | C6: {=AVERAGE( _xlfn._xlws.FILTER( CHOOSE({1,2,3,4,5}, F6, I6, L6, O6, R6), ISNUMBER(CHOOSE({1,2,3,4,5}, F6, I6, L6, O6, R6)) ) )} -> -9.0964493e-06 | D6: =C6*D$15 -> -170.71612 | F6: =G6/G$15 -> -4.5482247e-05 | G6: -1210 | I6: =J6/J$15 -> 0 | J6: 0 | L6: =M6/M$15 -> 0 | M6: 0 | O6: =P6/P$15 -> 0 | P6: 0 | R6: =S6/S$15 -> 0 | S6: 0 | U6: =V6/V$15 -> 0 | V6: 0
A7: Provision / credit loss allowance against other assets | C7: {=AVERAGE( _xlfn._xlws.FILTER( CHOOSE({1,2,3,4,5}, F7, I7, L7, O7, R7), ISNUMBER(CHOOSE({1,2,3,4,5}, F7, I7, L7, O7, R7)) ) )} -> 0.064986231 | D7: =C7*D$15 -> 1219618.4 | F7: =G7/G$15 -> 0.087977249 | G7: 2340528 | I7: =J7/J$15 -> 0.085989447 | J7: 1140717 | L7: =M7/M$15 -> 0.073598395 | M7: 624244 | O7: =P7/P$15 -> 0.023511009 | P7: 190136 | R7: =S7/S$15 -> 0.053855056 | S7: 658088 | U7: =V7/V$15 -> 0.027222931 | V7: 90219
A8: Charge / (reversal) of credit loss allowance against off-balance sheet obligations | C8: {=AVERAGE( _xlfn._xlws.FILTER( CHOOSE({1,2,3,4,5}, F8, I8, L8, O8, R8), ISNUMBER(CHOOSE({1,2,3,4,5}, F8, I8, L8, O8, R8)) ) )} -> 0.046210451 | D8: =C8*D$15 -> 867247.06 | F8: =G8/G$15 -> 0.17314475 | G8: 4606306 | I8: =J8/J$15 -> -0.0070776092 | J8: -93890 | L8: =M8/M$15 -> -0.15699393 | M8: -1331585 | O8: =P8/P$15 -> 0.19048943 | P8: 1540508 | R8: =S8/S$15 -> 0.03148962 | S8: 384791 | U8: =V8/V$15 -> -0.014855702 | V8: -49233
A9: Recoveries against written off / charged off bad debts | C9: {=AVERAGE( _xlfn._xlws.FILTER( CHOOSE({1,2,3,4,5}, F9, I9, L9, O9, R9), ISNUMBER(CHOOSE({1,2,3,4,5}, F9, I9, L9, O9, R9)) ) )} -> -0.075528923 | D9: =C9*D$15 -> -1417476.7 | F9: =G9/G$15 -> -0.029496515 | G9: -784719 | I9: =J9/J$15 -> -0.087233852 | J9: -1157225 | L9: =M9/M$15 -> -0.10681343 | M9: -905966 | O9: =P9/P$15 -> -0.10421356 | P9: -842786 | R9: =S9/S$15 -> -0.049887255 | S9: -609603 | U9: =V9/V$15 -> -0.18505703 | V9: -613294
A10: Recoveries against other assets written off | C10: {=AVERAGE( _xlfn._xlws.FILTER( CHOOSE({1,2,3,4,5}, F10, I10, L10, O10, R10), ISNUMBER(CHOOSE({1,2,3,4,5}, F10, I10, L10, O10, R10)) ) )} -> -0.0015889517 | D10: =C10*D$15 -> -29820.391 | F10: =G10/G$15 -> -6.6644647e-05 | G10: -1773 | I10: =J10/J$15 -> -0.0011323873 | J10: -15022 | L10: =M10/M$15 -> -0.00021328118 | M10: -1809 | O10: =P10/P$15 -> -0.0013260617 | P10: -10724 | R10: =S10/S$15 -> -0.0052063838 | S10: -63620 | U10: =V10/V$15 -> -0.012913384 | V10: -42796
A11: Write off of fixed assets | C11: {=AVERAGE( _xlfn._xlws.FILTER( CHOOSE({1,2,3,4,5}, F11, I11, L11, O11, R11), ISNUMBER(CHOOSE({1,2,3,4,5}, F11, I11, L11, O11, R11)) ) )} -> 0.0033102328 | D11: =C11*D$15 -> 62124.251 | F11: =G11/G$15 -> 0 | I11: =J11/J$15 -> 0 | L11: =M11/M$15 -> 0 | O11: =P11/P$15 -> 0.016551164 | P11: 133851 | R11: =S11/S$15 -> 0 | S11: 0 | U11: =V11/V$15 -> 0 | V11: 0
A12: Software written off | C12: {=AVERAGE( _xlfn._xlws.FILTER( CHOOSE({1,2,3,4,5}, F12, I12, L12, O12, R12), ISNUMBER(CHOOSE({1,2,3,4,5}, F12, I12, L12, O12, R12)) ) )} -> 0.0054918347 | D12: =C12*D$15 -> 103067.11 | F12: =G12/G$15 -> 0.027459173 | G12: 730518 | I12: =J12/J$15 -> 0 | J12: 0 | L12: =M12/M$15 -> 0 | O12: =P12/P$15 -> 0 | R12: =S12/S$15 -> 0 | S12: 0 | U12: =V12/V$15 -> 0 | V12: 0
A13: Other write offs and operational losses | C13: {=AVERAGE( _xlfn._xlws.FILTER( CHOOSE({1,2,3,4,5}, F13, I13, L13, O13, R13), ISNUMBER(CHOOSE({1,2,3,4,5}, F13, I13, L13, O13, R13)) ) )} -> 0.030296016 | D13: =C13*D$15 -> 568575.51 | F13: =G13/G$15 -> 0.032662418 | G13: 868944 | I13: =J13/J$15 -> 0.0079981733 | J13: 106102 | L13: =M13/M$15 -> 0.035547807 | M13: 301508 | O13: =P13/P$15 -> 0.075271683 | P13: 608730 | R13: =S13/S$15 -> 0 | S13: 0 | U13: =V13/V$15 -> 0 | V13: 0
A14: Bad debts written off directly | C14: {=AVERAGE( _xlfn._xlws.FILTER( CHOOSE({1,2,3,4,5}, F14, I14, L14, O14, R14), ISNUMBER(CHOOSE({1,2,3,4,5}, F14, I14, L14, O14, R14)) ) )} -> 0.0036326392 | D14: =C14*D$15 -> 68174.96 | F14: =G14/G$15 -> 0 | G14: 0 | I14: =J14/J$15 -> 0 | J14: 0 | L14: =M14/M$15 -> 0 | O14: =P14/P$15 -> 0.010024477 | P14: 81069 | R14: =S14/S$15 -> 0.0081387186 | S14: 99452 | U14: =V14/V$15 -> 0 | V14: 0
A15: Total | D15: =D4/C4 -> 18767336 | G15: 26603787 | J15: 13265779 | M15: 8481761 | P15: 8087105 | S15: 12219614 | V15: 3314081
B18: Specific | C18: General | D18: Total | E18: Specific | F18: General | G18: Total | H18: Specific | I18: General | J18: Total | K18: Specific | L18: General | M18: Total | N18: Specific | O18: General | P18: Total | Q18: Specific | R18: General | S18: Total | T18: Specific | U18: General | V18: Total
A19: Opening balance | H19: 78259477 | I19: 13911505 | J19: 92170982 | K19: 72845186 | L19: 11008308 | M19: 83853494 | N19: 70835763 | O19: 11063284 | P19: 81899047 | Q19: 72634967 | R19: 3730991 | S19: 76365958 | T19: 68465249 | U19: 3528347 | V19: 71993596
A20: Exchange adjustment | H20: 8019828 | I20: 831237 | J20: 8851065 | K20: 7453225 | L20: 691606 | M20: 8144831 | N20: 2670248 | O20: 222274 | P20: 2892522 | Q20: 974252 | R20: 47701 | S20: 1021953 | T20: 3108243 | U20: 183081 | V20: 3291324
A21: Charge for the year | H21: 16462892 | I21: 4857453 | J21: 21320345 | K21: 10153742 | L21: 3341192 | M21: 13494934 | N21: 12415018 | O21: 1613469 | P21: 14028487 | Q21: 9301182 | R21: 7636845 | S21: 16938027 | T21: 7524537 | U21: 528694 | V21: 8053231
A22: Reversal for the year | H22: -6643168 | I22: -1207976 | J22: -7851144 | K22: -6421672 | L22: -1129601 | M22: -7551273 | N22: -4492724 | O22: -1890719 | P22: -6383443 | Q22: -4525945 | R22: -352253 | S22: -4878198 | T22: -4256484 | U22: -420648 | V22: -4677132
A23: Net charge / (reversal) against advances | H23: 9819724 | I23: 3649477 | J23: 13469201 | K23: 3732070 | L23: 2211591 | M23: 5943661 | N23: 7922294 | O23: -277250 | P23: 7645044 | Q23: 4775237 | R23: 7284592 | S23: 12059829 | T23: 3268053 | U23: 108046 | V23: 3376099
A24: Charged off during the year agriculture financing | H24: -503799 | J24: -503799 | K24: -582438 | M24: -582438 | N24: -532280 | P24: -532280 | Q24: -750824 | S24: -750824 | T24: -604496 | V24: -604496
A25: Written off during the year | H25: -10675157 | J25: -10675157 | K25: -5333549 | M25: -5333549 | N25: -8050839 | P25: -8050839 | Q25: -6797869 | S25: -6797869 | T25: -1602082 | V25: -1602082
A26: Transferred out | K26: -67880 | M26: -67880
A27: Other movement | K27: 212863 | M27: 212863 | T27: -88483 | V27: -88483
A28: Closing balance | H28: 84920073 | I28: 18392219 | J28: 103312292 | K28: 78259477 | L28: 13911505 | M28: 92170982 | N28: 72845186 | O28: 11008308 | P28: 83853494 | Q28: 70835763 | R28: 11063284 | S28: 81899047 | T28: 72634967 | U28: 3730991 | V28: 76365958
B30: Stage 3, & Non-Performing | C30: Stage 1, 2, & Performing | D30: Total | E30: Stage 3, & Non-Performing | F30: Stage 1, 2, & Performing | G30: Total
A31: Opening balance - as restated | B31: =E42 -> 99179236 | C31: =F42 -> 38307009 | D31: =G42 -> 137486245 | E31: =F49+G49 -> 91132797 | F31: =D49+E49+H49 -> 38269669 | G31: =I49 -> 129402466
A32: Transfer to stage 1 | E32: =F50+G50 -> -13318 | F32: =D50+E50+H50 -> 13318 | G32: =I50 -> 0
A33: Transfer to stage 2 | E33: =F51+G51 -> -588849 | F33: =D51+E51+H51 -> 588849 | G33: =I51 -> 0
A34: Transfer to stage 3 | E34: =F52+G52 -> 3733133 | F34: =D52+E52+H52 -> -3733133 | G34: =I52 -> 0
A35: Exchange adjustment | E35: =F53+G53 -> -658411 | F35: =D53+E53+H53 -> -85245 | G35: =I53 -> -743656
A36: Charge for the year | E36: =F54+G54 -> 26780977 | F36: =D54+E54+H54 -> 37796996 | G36: =I54 -> 64577973
A37: Reversal for the year | E37: =F55+G55 -> -9466340 | F37: =D55+E55+H55 -> -34543445 | G37: =I55 -> -44009785
A38: Net charge / (reversal) against advances | B38: =B31*B44 -> 11455469 | C38: =C31*C44 -> 10779641 | D38: =D31*D44 -> 16595894 | E38: =F56+G56 -> 17314637 | F38: =D56+E56+H56 -> 3253551 | G38: =I56 -> 20568188
A39: Charged off during the year agriculture financing | E39: =F58+G58 -> -274326 | F39: =D58+E58+H58 -> 0 | G39: =I58 -> -274326
A40: Charged off during the year corporate, commercial and SME advances | E40: =F60+G60 -> -3534146 | F40: =D60+E60+H60 -> 0 | G40: =I60 -> -3534146
A41: Written off during the year | E41: =F61+G61 -> -7932281 | F41: =D61+E61+H61 -> 0 | G41: =I61 -> -7932281
A42: Closing balance | E42: =F62+G62 -> 99179236 | F42: =D62+E62+H62 -> 38307009 | G42: =I62 -> 137486245
A44: Net Charge/Opening Balance of Loss Allowance | B44: =(3*(E44+H44)+(2*(K44+N44))+(Q44+T44))/12 -> 0.11550269 | C44: =(3*(F44+I44)+(2*(L44+O44))+(R44+U44))/12 -> 0.28140128 | D44: =(3*(G44+J44)+(2*(M44+P44))+(S44+V44))/12 -> 0.12070949 | E44: =E38/E31 -> 0.18999348 | F44: =F38/F31 -> 0.08501644 | G44: =G38/G31 -> 0.15894742 | H44: =H23/H19 -> 0.12547648 | I44: =I23/I19 -> 0.26233517 | J44: =J23/J19 -> 0.14613277 | K44: =K23/K19 -> 0.051232898 | L44: =L23/L19 -> 0.20090199 | M44: =M23/M19 -> 0.070881495 | N44: =N23/N19 -> 0.11184031 | O44: =O23/O19 -> -0.025060371 | ... V44: =V23/V19 -> 0.046894435
...

Sheet Policy Rate
A1: Observation Date | B1: Series name | C1: Observation Value | D1: Unit | E1: Observation Status | F1: Sequence No.
A2: 45783 | B2: State Bank of Pakistan's Reverse Repo Rate | C2: 12 | D2: Percent | E2: Normal | F2: 10
A3: 45783 | B3: State Bank of Pakistan's Repo Rate | C3: 10 | D3: Percent | E3: Normal | F3: 20
A4: 45783 | B4: State Bank of Pakistan's Policy (Target) Rate | C4: 11 | D4: Percent | E4: Normal | F4: 30
A5: 45685 | B5: State Bank of Pakistan's Reverse Repo Rate | C5: 13 | D5: Percent | E5: Normal | F5: 10
A6: 45685 | B6: State Bank of Pakistan's Repo Rate | C6: 11 | D6: Percent | E6: Normal | F6: 20
A7: 45685 | B7: State Bank of Pakistan's Policy (Target) Rate | C7: 12 | D7: Percent | E7: Normal | F7: 30
A8: 45643 | B8: State Bank of Pakistan's Reverse Repo Rate | C8: 14 | D8: Percent | E8: Normal | F8: 10
A9: 45643 | B9: State Bank of Pakistan's Repo Rate | C9: 12 | D9: Percent | E9: Normal | F9: 20
A10: 45643 | B10: State Bank of Pakistan's Policy (Target) Rate | C10: 13 | D10: Percent | E10: Normal | F10: 30
A11: 45601 | B11: State Bank of Pakistan's Reverse Repo Rate | C11: 16 | D11: Percent | E11: Normal | F11: 10
A12: 45601 | B12: State Bank of Pakistan's Repo Rate | C12: 14 | D12: Percent | E12: Normal | F12: 20
A13: 45601 | B13: State Bank of Pakistan's Policy (Target) Rate | C13: 15 | D13: Percent | E13: Normal | F13: 30
... A91: 43437 | B91: State Bank of Pakistan's Policy (Target) Rate | C91: 10 | D91: Percent | E91: Normal | F91: 30
A95: Date | B95: Rate | C95: Days in Effect | D95: Weighted Rate
A96: 45657 | B96: 0.13 | C96: =A96-A97+1 -> 15 | D96: =(B96*C96) -> 1.95
A97: 45643 | B97: 0.13 | C97: =A97-A98 -> 42 | D97: =(B97*C97) -> 5.46
A98: 45601 | B98: 0.15 | C98: =A98-A99 -> 53 | D98: =(B98*C98) -> 7.95
A99: 45548 | B99: 0.175 | C99: =A99-A100 -> 45 | D99: =(B99*C99) -> 7.875
A100: 45503 | B100: 0.195 | C100: =A100-A101 -> 49 | D100: =(B100*C100) -> 9.555
A101: 45454 | B101: 0.205 | C101: =A101-A102 -> 162 | D101: =(B101*C101) -> 33.21
A102: 45292 | B102: 0.22
C103: =SUM(C96:C102) -> 366 | D103: =SUM(D96:D102)/C103 -> 0.18032787
A105: Date | B105: Rate | C105: Days in Effect | D105: Weighted Rate
A106: 45291 | B106: 0.22 | C106: =A106-A107+1 -> 188 | D106: =(B106*C106) -> 41.36
A107: 45104 | B107: 0.22 | C107: =A107-A108 -> 83 | D107: =(B107*C107) -> 18.26
A108: 45021 | B108: 0.21 | C108: =A108-A109 -> 33 | D108: =(B108*C108) -> 6.93
A109: 44988 | B109: 0.2 | C109: =A109-A110 -> 38 | D109: =(B109*C109) -> 7.6
A110: 44950 | B110: 0.17 | C110: =A110-A111 -> 23 | D110: =(B110*C110) -> 3.91
A111: 44927 | B111: 0.16
C112: =SUM(C106:C111) -> 365 | D112: =SUM(D106:D111)/C112 -> 0.21386301
A114: Date | B114: Rate | C114: Days in Effect | D114: Weighted Rate
A115: 44926 | B115: 0.16 | C115: =A115-A116+1 -> 34 | D115: =(B115*C115) -> 5.44
A116: 44893 | B116: 0.16 | C116: =A116-A117 -> 138 | D116: =(B116*C116) -> 22.08
A117: 44755 | B117: 0.15 | C117: =A117-A118 -> 50 | D117: =(B117*C117) -> 7.5
A118: 44705 | B118: 0.1375 | C118: =A118-A119 -> 46 | D118: =(B118*C118) -> 6.325
A119: 44659 | B119: 0.1225 | C119: =A119-A120 -> 97 | D119: =(B119*C119) -> 11.8825
A120: 44562 | B120: 0.0975
C121: =SUM(C115:C120) -> 365 | D121: =SUM(D115:D120)/C121 -> 0.14582877
A123: Date | B123: Rate | C123: Days in Effect | D123: Weighted Rate
...

Sheet National Advances
A1: Macroeconomic Data | C1: The figures for these categories are taken from Quarterly Compendium: Statistics of the Banking System, issued by the State Bank of Pakistan
C2: PKR | D2: Forecasted Growth | F2: PKR | G2: YoY Growth | I2: PKR | J2: YoY Growth | L2: PKR | M2: YoY Growth | O2: PKR | P2: YoY Growth | R2: PKR | S2: YoY Growth | U2: PKR
A3: National Total | C3: 25 Forecast | D3: CAGR | F3: 24 | I3: 23 | L3: 22 | O3: 21 | R3: 20 | U3: 19
A4: Corporate Sector | C4: =(1+D4)*F4 -> 9.3759508e+09 | D4: =(PRODUCT(1+G4,1+J4,1+M4,1+P4,1+S4)^(1/5))-1 -> 0.10646433 | F4: =12304672000-2101528000-F11 -> 8473794000 | G4: =F4/I4-1 -> 0.29398183 | I4: =(8878428-1924342)*1000-I11 -> 6548619000 | J4: =I4/L4-1 -> -0.0079819006 | L4: =(9022077-1756988)*1000-L11 -> 6601310000 | M4: =L4/O4-1 -> 0.15011833 | O4: =(7731109-1653957)*1000-O11 -> 5739679000 | P4: =O4/R4-1 -> 0.15881803 | R4: =(6421776-1238574)*1000-R11 -> 4953046000 | S4: =R4/U4-1 -> -0.030647916 | U4: =(6356658-1247012)*1000 -> 5109646000
A5: SMEs Sector | C5: =(1+D5)*F5 -> 6.8317646e+08 | D5: =(PRODUCT(1+G5,1+J5,1+M5,1+P5,1+S5)^(1/5))-1 -> 0.077568799 | F5: =677718000-43720000 -> 633998000 | G5: =F5/I5-1 -> 0.25187931 | I5: =(537795-31358)*1000 -> 506437000 | J5: =I5/L5-1 -> 0.025834392 | L5: =(532580-38897)*1000 -> 493683000 | M5: =L5/O5-1 -> 0.037467374 | O5: =(518631-42777)*1000 -> 475854000 | P5: =O5/R5-1 -> 0.13344989 | R5: =(460690-40862)*1000 -> 419828000 | S5: =R5/U5-1 -> -0.037925835 | U5: =(480009-43631)*1000 -> 436378000
A6: Agriculture Sector | C6: =(1+D6)*F6 -> 6.4164735e+08 | D6: =(PRODUCT(1+G6,1+J6,1+M6,1+P6,1+S6)^(1/5))-1 -> 0.10916088 | F6: 578498000 | G6: =F6/I6-1 -> 0.15302958 | I6: 501720000 | J6: =I6/L6-1 -> 0.11859487 | L6: 448527000 | M6: =L6/O6-1 -> 0.10789261 | O6: 404847000 | P6: =O6/R6-1 -> 0.19764109 | R6: 338037000 | S6: =R6/U6-1 -> -0.019076582 | U6: 344611000
A7: Consumer sector | C7: =(1+D7)*F7 -> 9.7370978e+08 | D7: =(PRODUCT(1+G7,1+J7,1+M7,1+P7,1+S7)^(1/5))-1 -> 0.092532527 | F7: 891241000 | G7: =F7/I7-1 -> 0.093806263 | I7: 814807000 | J7: =I7/L7-1 -> -0.090523804 | L7: 895908000 | M7: =L7/O7-1 -> 0.091335659 | O7: 820928000 | P7: =O7/R7-1 -> 0.29233801 | R7: 635227000 | S7: =R7/U7-1 -> 0.10944472 | U7: 572563000
A8: Commodity financing | C8: =(1+D8)*F8 -> 1.5626276e+09 | D8: =(PRODUCT(1+G8,1+J8,1+M8,1+P8,1+S8)^(1/5))-1 -> 0.11825291 | F8: 1397383000 | G8: =F8/I8-1 -> -0.0068901653 | I8: 1407078000 | J8: =I8/L8-1 -> 0.11590581 | L8: 1260929000 | M8: =L8/O8-1 -> 0.27263341 | O8: 990803000 | P8: =O8/R8-1 -> 0.18887705 | R8: 833394000 | S8: =R8/U8-1 -> 0.042881848 | U8: 799126000
A9: Staff Loans | C9: =(1+D9)*F9 -> 4.3733388e+08 | D9: =(PRODUCT(1+G9,1+J9,1+M9,1+P9,1+S9)^(1/5))-1 -> 0.19383794 | F9: 366326000 | G9: =F9/I9-1 -> 0.20870151 | I9: 303074000 | J9: =I9/L9-1 -> 0.24490249 | L9: 243452000 | M9: =L9/O9-1 -> 0.22770779 | O9: 198298000 | P9: =O9/R9-1 -> 0.20916364 | R9: 163996000 | S9: =R9/U9-1 -> 0.085656408 | U9: 151057000
A10: Trade Finance | C10: =(1+D10)*F10 -> 2.3747166e+09 | D10: =(PRODUCT(1+G10,1+J10,1+M10,1+P10,1+S10)^(1/5))-1 -> 0.10696598 | F10: =2101528000+43720000 -> 2145248000 | G10: =F10/I10-1 -> 0.096920796 | I10: =(1924342+31358)*1000 -> 1955700000 | J10: =I10/L10-1 -> 0.088989551 | L10: =(1756988+38897)*1000 -> 1795885000 | M10: =L10/O10-1 -> 0.058436384 | O10: =(1653957+42777)*1000 -> 1696734000 | P10: =O10/R10-1 -> 0.32615778 | R10: =(1238574+40862)*1000 -> 1279436000 | S10: =R10/U10-1 -> -0.0086832687 | U10: =(1247012+43631)*1000 -> 1290643000
A11: Financial | C11: =(1+D11)*F11 -> 2.5419054e+09 | D11: =(PRODUCT(1+G11,1+J11,1+M11,1+P11,1+S11)^(1/5))-1 -> 0.46986173 | F11: 1729350000 | G11: =F11/I11-1 -> 3.265082 | I11: 405467000 | J11: =I11/L11-1 -> -0.38915362 | L11: 663779000 | M11: =L11/O11-1 -> 0.96690995 | O11: 337473000 | P11: =O11/R11-1 -> 0.46627939 | R11: 230156000 | S11: =R11/U11-1 -> -0.086892699 | U11: 252058000
A12: Others | C12: =(1+D12)*F12 -> 9.3257069e+08 | D12: =(PRODUCT(1+G12,1+J12,1+M12,1+P12,1+S12)^(1/5))-1 -> 0.33502451 | F12: 698542000 | G12: =F12/I12-1 -> 0.062109525 | I12: 657693000 | J12: =I12/L12-1 -> 1.7190543 | L12: 241883000 | M12: =L12/O12-1 -> 0.0046977803 | O12: 240752000 | P12: =O12/R12-1 -> 0.41105862 | R12: 170618000 | S12: =R12/U12-1 -> 0.035806217 | U12: 164720000
A13: Total | C13: =SUM(C4:C12) -> 1.9523639e+10 | D13: =(PRODUCT(1+G13,1+J13,1+M13,1+P13,1+S13)^(1/5))-1 -> 0.13147408 | F13: 16914380000 | G13: =F13/I13-1 -> 0.2911154 | I13: =SUM(I4:I12) -> 13100595000 | J13: =I13/L13-1 -> 0.036000489 | L13: =SUM(L4:L12) -> 12645356000 | M13: =L13/O13-1 -> 0.15955335 | O13: =SUM(O4:O12) -> 10905368000 | P13: =O13/R13-1 -> 0.20852002 | R13: =SUM(R4:R12) -> 9023738000 | S13: =R13/U13-1 -> -0.010642047 | U13: =SUM(U4:U12) -> 9120802000
C16: PKR | D16: Forecasted Proportion | F16: PKR | G16: Proportion of National Total | I16: PKR | J16: Proportion of National Total | L16: PKR | M16: Proportion of National Total | O16: PKR | P16: Proportion of National Total | R16: PKR | S16: Proportion of National Total | U16: PKR | V16: Proportion of National Total
A17: HBL | C17: 25 Forecast | D17: CAGR | F17: 24 | G17: 24 | I17: 23 | J17: 23 | L17: 22 | M17: 22 | O17: 21 | P17: 21 | R17: 20 | S17: 20 | U17: 19 | V17: 19
A18: Corporate and Commercial | C18: =(1+D18)*F18 -> 1.38298e+09 | D18: =(PRODUCT(1+G18,1+J18,1+M18,1+P18,1+S18)^(1/5))-1 -> 0.12051965 | F18: =F29+F30+(F34*0.8)-F21 -> 1.2342309e+09 | G18: =F18/(F4+F8) -> 0.12503382 | I18: =I29+I30+(I34*0.8)-I21 -> 8.9840339e+08 | J18: =I18/(I4+I8) -> 0.11292579 | L18: =L29+L30+(L34*0.8)-L21 -> 1.0445438e+09 | M18: =L18/(L4+L8+L5) -> 0.12500641 | O18: =O29+O30+(O34*0.8)-O21 -> 8.6655208e+08 | P18: =O18/(O4+O8+O5) -> 0.12024864 | R18: =R29+R30+(R34*0.8)-R21 -> 7.4120249e+08 | S18: =R18/(R4+R8+R5) -> 0.11942805 | U18: =U29+U30+(U34*0.8)-U21 -> 7.1161037e+08 | V18: =U18/(U4+U8+U5) -> 0.11215028
A19: Consumer and Retail | C19: =(1+D19)*F19 -> 3.4251513e+08 | D19: =(PRODUCT(1+G19,1+J19,1+M19,1+P19,1+S19)^(1/5))-1 -> 0.21239812 | F19: =F31+F32+(F34*0.2) -> 2.8251045e+08 | G19: =F19/(F7+F9) -> 0.22464842 | I19: =I31+I32+(I34*0.2) -> 2.4569749e+08 | J19: =I19/(I7+I9) -> 0.21978859 | L19: =L31+L32+(L34*0.2) -> 2.3885472e+08 | M19: =L19/(L7+L9) -> 0.20963938 | O19: =O31+O32+(O34*0.2) -> 2.0495841e+08 | P19: =O19/(O7+O9) -> 0.20109221 | R19: =R31+R32+(R34*0.2) -> 1.6541858e+08 | S19: =R19/(R7+R9) -> 0.20697425 | U19: =U31+U32+(U34*0.2) -> 1.6127346e+08 | V19: =U19/(U7+U9) -> 0.22287037
A20: Agriculture | C20: =(1+D20)*F20 -> 81114956 | D20: =(PRODUCT(1+G20,1+J20,1+M20,1+P20,1+S20)^(1/5))-1 -> 0.11020495 | F20: =F33 -> 73063046 | G20: =F20/F6 -> 0.12629784 | I20: =I33 -> 55840338 | J20: =I20/I6 -> 0.11129781 | L20: =L33 -> 53474938 | M20: =L20/L6 -> 0.11922345 | O20: =O33 -> 39183225 | P20: =O20/O6 -> 0.096785266 | R20: =R33 -> 33034776 | S20: =R20/R6 -> 0.097725326 | U20: =U33 -> 33841753 | V20: =U20/U6 -> 0.098202764
A21: SME | C21: =(1+D21)*F21 -> 1.233835e+08 | D21: =(PRODUCT(1+G21,1+J21,1+M21,1+P21,1+S21)^(1/5))-1 -> 0.072899967 | F21: 115000000 | G21: =F21/F5 -> 0.18138858 | I21: 103000000 | J21: =I21/I5 -> 0.20338166 | M21: =L21/L5 -> 0 | P21: =O21/O5 -> 0 | S21: =R21/R5 -> 0 | V21: =U21/U5 -> 0
A22: International | C22: =(1+D22)*F22 -> 4.5509602e+08 | D22: =(PRODUCT(1+G22,1+J22,1+M22,1+P22,1+S22)^(1/5))-1 -> 0.16790236 | F22: =F35 -> 3.8966958e+08 | G22: =F22/F10 -> 0.18164314 | I22: =I35 -> 3.5365547e+08 | J22: =I22/I10 -> 0.18083319 | L22: =L35 -> 2.8519967e+08 | M22: =L22/L10 -> 0.15880731 | O22: =O35 -> 2.7428257e+08 | P22: =O22/O10 -> 0.16165325 | R22: =R35 -> 2.0065568e+08 | S22: =R22/R10 -> 0.15683135 | U22: =U35 -> 1.9138095e+08 | V22: =U22/U10 -> 0.14828341
A23: Microfinance | C23: =(1+D23)*F23 -> 88831447 | D23: =(PRODUCT(1+G23,1+J23,1+M23,1+P23,1+S23)^(1/5))-1 -> 0.21581911 | F23: =F36 -> 73063046 | G23: =F23/F12 -> 0.10459363 | I23: =I36 -> 93067230 | J23: =I23/I12 -> 0.14150558 | L23: =L36 -> 89124896 | M23: =L23/L12 -> 0.36846284 | O23: =O36 -> 57267790 | P23: =O23/O12 -> 0.23787046 | R23: =R36 -> 41599348 | S23: =R23/R12 -> 0.2438157 | U23: =U36 -> 31507839 | V23: =U23/U12 -> 0.1912812
A24: Financial Institution | C24: =(1+D24)*F24 -> 3.163451e+08 | D24: =(PRODUCT(1+G24,1+J24,1+M24,1+P24,1+S24)^(1/5))-1 -> 0.18084229 | F24: =F37 -> 2.6789784e+08 | G24: =F24/F11 -> 0.15491244 | I24: =I37 -> 1.1168068e+08 | J24: =I24/I11 -> 0.27543715 | L24: =L37 -> 71299917 | M24: =L24/L11 -> 0.10741514 | O24: =O37 -> 64803025 | P24: =O24/O11 -> 0.19202433 | R24: =R37 -> 41599348 | S24: =R24/R11 -> 0.18074414 | U24: =U37 -> 39676538 | V24: =U24/U11 -> 0.15741035
A25: Gross Advances | C25: =SUM(C18:C24) -> 2.7902661e+09 | D25: =(PRODUCT(1+G25,1+J25,1+M25,1+P25,1+S25)^(1/5))-1 -> 0.14015791 | F25: =SUM(F18:F24) -> 2435434872 | G25: =F25/F13 -> 0.14398606 | I25: =SUM(I18:I24) -> 1861344592 | J25: =I25/I13 -> 0.14208092 | L25: =SUM(L18:L24) -> 1.7824979e+09 | M25: =L25/L13 -> 0.14096068 | O25: =SUM(O18:O24) -> 1.5070471e+09 | P25: =O25/O13 -> 0.13819314 | R25: =SUM(R18:R24) -> 1223510222 | S25: =R25/R13 -> 0.13558796 | U25: =SUM(U18:U24) -> 1.1692909e+09 | V25: =U25/U13 -> 0.12820045
C27: The proportions for these categories are taken from HBL Investor Presentation issued quarterly
A29: Corporate | E29: 0.44 | F29: =F$38*E29 -> 1.0715913e+09 | H29: 0.39 | I29: =I$38*H29 -> 7.2592439e+08 | K29: 0.43 | L29: =L$38*K29 -> 7.6647411e+08 | N29: 0.43 | O29: =O$38*N29 -> 6.4803025e+08 | Q29: 0.446 | R29: =R$38*Q29 -> 5.4568556e+08 | T29: 0.446 | U29: =U$38*T29 -> 5.2046282e+08
A30: Commercial | E30: 0.05 | F30: =F$38*E30 -> 1.2177174e+08 | H30: 0.06 | I30: =I$38*H30 -> 1.1168068e+08 | K30: 0.06 | L30: =L$38*K30 -> 1.0694988e+08 | N30: 0.061 | O30: =O$38*N30 -> 91929873 | Q30: 0.059 | R30: =R$38*Q30 -> 72187103 | T30: 0.059 | U30: =U$38*T30 -> 68850463
A31: Consumer | E31: 0.05 | F31: =F$38*E31 -> 1.2177174e+08 | H31: 0.06 | I31: =I$38*H31 -> 1.1168068e+08 | K31: 0.06 | L31: =L$38*K31 -> 1.0694988e+08 | N31: 0.068 | O31: =O$38*N31 -> 1.024792e+08 | Q31: 0.061 | R31: =R$38*Q31 -> 74634124 | T31: 0.051 | U31: =U$38*T31 -> 59514807
A32: Retail Lending | E32: 0.05 | F32: =F$38*E32 -> 1.2177174e+08 | H32: 0.05 | I32: =I$38*H32 -> 93067230 | K32: 0.05 | L32: =L$38*K32 -> 89124896 | N32: 0.047 | O32: =O$38*N32 -> 70831214 | Q32: 0.049 | R32: =R$38*Q32 -> 59952001 | T32: 0.061 | U32: =U$38*T32 -> 71184377
A33: Agriculture | E33: 0.03 | F33: =F$38*E33 -> 73063046 | H33: 0.03 | I33: =I$38*H33 -> 55840338 | K33: 0.03 | L33: =L$38*K33 -> 53474938 | N33: 0.026 | O33: =O$38*N33 -> 39183225 | Q33: 0.027 | R33: =R$38*Q33 -> 33034776 | T33: 0.029 | U33: =U$38*T33 -> 33841753
A34: Islamic | E34: 0.08 | F34: =F$38*E34 -> 1.9483479e+08 | H34: 0.11 | I34: =I$38*H34 -> 2.0474791e+08 | K34: 0.12 | L34: =L$38*K34 -> 2.1389975e+08 | N34: 0.105 | O34: =O$38*N34 -> 1.5823995e+08 | Q34: 0.126 | R34: =R$38*Q34 -> 1.5416229e+08 | T34: 0.131 | U34: =U$38*T34 -> 1.5287137e+08
A35: International | E35: 0.16 | F35: =F$38*E35 -> 3.8966958e+08 | H35: 0.19 | I35: =I$38*H35 -> 3.5365547e+08 | K35: 0.16 | L35: =L$38*K35 -> 2.8519967e+08 | N35: 0.182 | O35: =O$38*N35 -> 2.7428257e+08 | Q35: 0.164 | R35: =R$38*Q35 -> 2.0065568e+08 | T35: 0.164 | U35: =U$38*T35 -> 1.9138095e+08
A36: Microfinance | E36: 0.03 | F36: =F$38*E36 -> 73063046 | H36: 0.05 | I36: =I$38*H36 -> 93067230 | K36: 0.05 | L36: =L$38*K36 -> 89124896 | N36: 0.038 | O36: =O$38*N36 -> 57267790 | Q36: 0.034 | R36: =R$38*Q36 -> 41599348 | T36: 0.027 | U36: =U$38*T36 -> 31507839
